<?xml version="1.0"?>
<robot xmlns:sensor="http://playerstage.sourceforge.net/gazebo/xmlschema/#sensor"
       xmlns:controller="http://playerstage.sourceforge.net/gazebo/xmlschema/#controller"
       xmlns:interface="http://playerstage.sourceforge.net/gazebo/xmlschema/#interface"
       xmlns:xacro="http://playerstage.sourceforge.net/gazebo/xmlschema/#interface">

  <xacro:include filename="$(find kuka_lwr4_description)/defs/util_defs.xml"/>

  <property name="arm_elem_base_mass" value="2.0"/>
  <property name="arm_elem_link_mass" value="2.0"/>
  <property name="arm_elem_end_link_mass" value="2.0"/>
  <property name="arm_elem_ball_link_mass" value="2.0"/>

  <property name="arm_velocity_scale_factor" value="1"/>

  <macro name="kuka_lwr_arm" params="parent name right gazebo transmission collisionsimple visualsimple *origin">

    <joint name="${parent}_${name}_arm_base_joint" type="fixed">
      <insert_block name="origin"/>
      <parent link="${parent}"/>
      <child link="base"/>
    </joint>

    <link name="base">
      <inertial>
        <mass value="${arm_elem_base_mass}"/>
        <origin xyz="0 0 0.055"/>
        <cylinder_inertia_def radius="0.06" length="0.11"
                              mass="${arm_elem_base_mass}"/>
      </inertial>

      <xacro:unless value="${visualsimple}">
      <visual>
        <origin xyz="0 0 0" rpy="0 0 ${M_PI}"/>
        <geometry>
          <mesh filename="package://kuka_lwr4_description/meshes/kuka_colour/base.obj"/>
        </geometry>
        <material name="Blue"/>
      </visual>
      </xacro:unless>
      <xacro:if value="${visualsimple}">
      <visual>
        <origin rpy="0 0 0" xyz="0.04 0 0.03"/>
        <geometry>
          <box size="0.08 0.12 0.06"/>
        </geometry>
        <material name="Blue"/>
      </visual>
      <visual>
        <origin rpy="0 0 0" xyz="0 0 0.05"/>
        <geometry>
          <cylinder length="0.1" radius="0.06"/>
        </geometry>
        <material name="Blue"/>
      </visual>
      </xacro:if>

      <xacro:unless value="${collisionsimple}">
      <collision>
        <origin xyz="0 0 0.055" rpy="0 0 ${M_PI}"/>
        <geometry>
          <mesh filename="package://kuka_lwr4_description/meshes/lwr/convex/arm_base_convex.stl"/>
        </geometry>
      </collision>
      </xacro:unless>
      <xacro:if value="${collisionsimple}">
      <collision>
        <origin rpy="0 0 0" xyz="0.04 0 0.03"/>
        <geometry>
          <box size="0.08 0.12 0.06"/>
        </geometry>
      </collision>
      <collision>
        <origin rpy="0 0 0" xyz="0 0 0.05"/>
        <geometry>
          <cylinder length="0.1" radius="0.06"/>
        </geometry>
      </collision>
      </xacro:if>
    </link>

    <xacro:if value="${gazebo}">
    <gazebo reference="calib_${name}_arm_base_link">
      <turnGravityOff>true</turnGravityOff>
    </gazebo>
    </xacro:if>

    <joint name="${name}_arm_0_joint" type="revolute">
      <origin xyz="0 0 0.11" rpy="0 0 ${M_PI}"/>
      <axis xyz="0 0 1"/>
      <limit lower="${-170 * M_PI / 180}" upper="${170 * M_PI / 180}"
             effort="204" velocity="${arm_velocity_scale_factor * 110 * M_PI / 180}" />
      <safety_controller soft_lower_limit="${-168 * M_PI / 180}"
                         soft_upper_limit="${168 * M_PI / 180}"
                         k_position="30"
                         k_velocity="30"/>
      <dynamics damping="1.0"/>
      <parent link="base"/>
      <child link="${name}_arm_1_link"/>
    </joint>

    <link name="${name}_arm_1_link">
      <inertial>
        <mass value="${arm_elem_link_mass}"/>
        <origin rpy="0 0 0" xyz="0 -0.06 0.130"/>
        <cuboid_inertia_def length="0.12" width="0.06" height="0.260"
                            mass="${arm_elem_link_mass}"/>
      </inertial>

      <xacro:unless value="${visualsimple}">
      <visual>
        <origin rpy="0 0 4.71238898" xyz="0 0 0.2"/>
        <geometry>
          <mesh filename="package://kuka_lwr4_description/meshes/kuka_colour/link1.obj"/>
        </geometry>
        <material name="Blue"/>
      </visual>
      <visual>
        <origin rpy="0 0 4.71238898" xyz="0 0 0.2"/>
        <geometry>
          <mesh filename="package://kuka_lwr4_description/meshes/kuka/link1_m.obj"/>
        </geometry>
        <material name="Grey"/>
      </visual>
      <visual>
        <origin rpy="0 0 0" xyz="0 0 0"/>
        <geometry>
          <mesh filename="package://kuka_lwr4_description/meshes/kuka/kuka_ring.obj"/>
        </geometry>
        <material name="Grey"/>
      </visual>
      </xacro:unless>
      <xacro:if value="${visualsimple}">
      <visual>
        <origin rpy="0 0 0" xyz="0 0 0.05"/>
        <geometry>
          <cylinder length="0.1" radius="0.06"/>
        </geometry>
        <material name="Blue"/>
      </visual>
      <visual>
        <origin rpy="0 0 0" xyz="0 -0.04 0.12"/>
        <geometry>
          <cylinder length="0.05" radius="0.03"/>
        </geometry>
        <material name="Blue"/>
      </visual>
      <visual>
        <origin rpy="0 0 0" xyz="0 -0.04 0.2"/>
        <geometry>
          <sphere radius="0.06"/>
        </geometry>
        <material name="Blue"/>
      </visual>
      </xacro:if>

      <xacro:unless value="${collisionsimple}">
      <collision>
        <origin xyz="0 0 0" rpy="0 0 0"/>
        <geometry>
          <mesh filename="package://kuka_lwr4_description/meshes/lwr/convex/arm_segment_a_convex.stl"/>
        </geometry>
      </collision>
      </xacro:unless>
      <xacro:if value="${collisionsimple}">
      <collision>
        <origin rpy="0 0 0" xyz="0 0 0.05"/>
        <geometry>
          <cylinder length="0.1" radius="0.06"/>
        </geometry>
      </collision>
      <collision>
        <origin rpy="0 0 0" xyz="0 -0.04 0.2"/>
        <geometry>
          <sphere radius="0.06"/>
      </geometry>
      </collision>
      </xacro:if>
    </link>

    <xacro:if value="${gazebo}">
    <gazebo reference="${name}_arm_1_link">
      <gravity>0</gravity>
    </gazebo>
    </xacro:if>

    <xacro:if value="${transmission}">
    <transmission name="${name}_arm_0_trans" type="SimpleTransmission">
      <actuator name="${name}_arm_0_motor"/>
      <joint name="${name}_arm_0_joint"/>
      <mechanicalReduction>1.0</mechanicalReduction>
    </transmission>
    </xacro:if>

    <!-- Third segment of the arm. Joint along y-axis -->
    <joint name="${name}_arm_1_joint" type="revolute">
      <origin xyz="0 0 0.2" rpy="0 0 0"/>
      <axis xyz="0 1 0"/>
      <limit lower="${-120 * M_PI / 180}" upper="${120 * M_PI / 180}"
             effort="306" velocity="${arm_velocity_scale_factor * 110 * M_PI / 180}" />
      <safety_controller soft_lower_limit="${-118 * M_PI / 180}"
                         soft_upper_limit="${118 * M_PI / 180}"
                         k_position="30"
                         k_velocity="30"/>
      <dynamics damping="1.0" friction="10"/>
      <parent link="${name}_arm_1_link"/>
      <child link="${name}_arm_2_link"/>
    </joint>

    <link name="${name}_arm_2_link">
      <inertial>
        <mass value="${arm_elem_link_mass}"/>
        <origin rpy="0 0 0" xyz="0 0.06 ${0.130 - 0.06}"/>
        <cuboid_inertia_def length="0.12" width="0.06" height="0.260"
                            mass="${arm_elem_link_mass}"/>
      </inertial>

      <xacro:unless value="${visualsimple}">
      <visual>
        <origin rpy="0 0 4.71238898" xyz="0 0 0"/>
        <geometry>
          <mesh filename="package://kuka_lwr4_description/meshes/kuka_colour/link2.obj"/>
        </geometry>
        <material name="Blue"/>
      </visual>
      <visual>
        <origin rpy="0 0 4.71238898" xyz="0 0 0"/>
        <geometry>
          <mesh filename="package://kuka_lwr4_description/meshes/kuka/link2_m.obj"/>
        </geometry>
        <material name="Grey"/>
      </visual>
      <visual>
        <origin rpy="1.570796327 0 0" xyz="0 0 0"/>
        <geometry>
          <mesh filename="package://kuka_lwr4_description/meshes/kuka/kuka_ring.obj"/>
        </geometry>
        <material name="Grey"/>
      </visual>
      </xacro:unless>
      <xacro:if value="${visualsimple}">
      <visual>
        <origin rpy="0 0 0" xyz="0 0 0.15"/>
        <geometry>
          <cylinder length="0.1" radius="0.06"/>
        </geometry>
        <material name="Blue"/>
      </visual>
      <visual>
        <origin rpy="0 0 0" xyz="0 0.04 0.08"/>
        <geometry>
          <cylinder length="0.05" radius="0.03"/>
        </geometry>
        <material name="Blue"/>
      </visual>
      <visual>
        <origin rpy="0 0 0" xyz="0 0.04 0"/>
        <geometry>
          <sphere radius="0.06"/>
        </geometry>
      <material name="Blue"/>
      </visual>
      </xacro:if>

      <xacro:unless value="${collisionsimple}">
      <collision>
        <origin xyz="0 0 0.2" rpy="${M_PI} 0 0"/>
        <geometry>
          <mesh filename="package://kuka_lwr4_description/meshes/lwr/convex/arm_segment_b_convex.stl"/>
        </geometry>
      </collision>
      </xacro:unless>
      <xacro:if value="${collisionsimple}">
      <collision>
        <origin rpy="0 0 0" xyz="0 0 0.15"/>
        <geometry>
          <cylinder length="0.1" radius="0.06"/>
        </geometry>
      </collision>
      <collision>
        <origin rpy="0 0 0" xyz="0 0.04 0"/>
        <geometry>
        <sphere radius="0.06"/>
      </geometry>
      </collision>
      </xacro:if>
    </link>

    <xacro:if value="${gazebo}">
    <gazebo reference="${name}_arm_2_link">
      <gravity>0</gravity>
    </gazebo>
    </xacro:if>
    
    <xacro:if value="${transmission}">
    <transmission name="${name}_arm_1_trans" type="SimpleTransmission">
      <actuator name="${name}_arm_1_motor"/>
      <joint name="${name}_arm_1_joint"/>
      <mechanicalReduction>1.0</mechanicalReduction>
    </transmission>
    </xacro:if>

    <joint name="${name}_arm_2_joint" type="revolute">
      <origin xyz="0 0 0.20" rpy="0 0 0"/>
      <axis xyz="0 0 1"/>
      <limit lower="${-170 * M_PI / 180}" upper="${170 * M_PI / 180}"
             effort="204" velocity="${arm_velocity_scale_factor * 130 * M_PI / 180}" />
      <safety_controller soft_lower_limit="${-168 * M_PI / 180}"
                         soft_upper_limit="${168 * M_PI / 180}"
                         k_position="30"
                         k_velocity="30"/>
      <dynamics damping="1.0"/>
      <parent link="${name}_arm_2_link"/>
      <child link="${name}_arm_3_link"/>
    </joint>

    <link name="${name}_arm_3_link">
      <inertial>
        <mass value="${arm_elem_link_mass}"/>
        <origin rpy="0 0 0" xyz="0 0.06 0.130"/>
        <cuboid_inertia_def length="0.12" width="0.06" height="0.260"
                            mass="${arm_elem_link_mass}"/>
      </inertial>

      <xacro:unless value="${visualsimple}">
      <visual>
        <origin rpy="0 0 4.71238898" xyz="0 0 0.2"/>
        <geometry>
          <mesh filename="package://kuka_lwr4_description/meshes/kuka_colour/link3.obj"/>
        </geometry>
        <material name="Blue"/>
      </visual>
      <visual>
        <origin rpy="0 0 4.71238898" xyz="0 0 0.2"/>
        <geometry>
          <mesh filename="package://kuka_lwr4_description/meshes/kuka/link3_m.obj"/>
        </geometry>
        <material name="Grey"/>
      </visual>
      <visual>
        <origin rpy="0 0 0" xyz="0 0 0"/>
        <geometry>
          <mesh filename="package://kuka_lwr4_description/meshes/kuka/kuka_ring.obj"/>
        </geometry>
        <material name="Grey"/>
      </visual>
      </xacro:unless>
      <xacro:if value="${visualsimple}">
      <visual>
        <origin rpy="0 0 0" xyz="0 0 0.05"/>
        <geometry>
          <cylinder length="0.1" radius="0.06"/>
        </geometry>
        <material name="Blue"/>
      </visual>
      <visual>
        <origin rpy="0 0 0" xyz="0 0.04 0.12"/>
        <geometry>
          <cylinder length="0.05" radius="0.03"/>
        </geometry>
        <material name="Blue"/>
      </visual>
      <visual>
        <origin rpy="0 0 0" xyz="0 0.04 0.2"/>
        <geometry>
          <sphere radius="0.06"/>
        </geometry>
        <material name="Blue"/>
      </visual>
      </xacro:if>

      <xacro:unless value="${collisionsimple}">
      <collision>
        <origin xyz="0 0 0" rpy="0 0 ${M_PI}"/>
        <geometry>
          <mesh filename="package://kuka_lwr4_description/meshes/lwr/convex/arm_segment_a_convex.stl"/>
        </geometry>
      </collision>
      </xacro:unless>
      <xacro:if value="${collisionsimple}">
      <collision>
        <origin rpy="0 0 0" xyz="0 0 0.05"/>
        <geometry>
          <cylinder length="0.1" radius="0.06"/>
        </geometry>
      </collision>
      <collision>
        <origin rpy="0 0 0" xyz="0 0.04 0.2"/>
        <geometry>
          <sphere radius="0.06"/>
        </geometry>
      </collision>
      </xacro:if>
    </link>

    <xacro:if value="${gazebo}">
    <gazebo reference="${name}_arm_3_link">
      <turnGravityOff>true</turnGravityOff>
    </gazebo>
    </xacro:if>

    <xacro:if value="${transmission}">
    <transmission name="${name}_arm_2_trans" type="SimpleTransmission">
      <actuator name="${name}_arm_2_motor"/>
      <joint name="${name}_arm_2_joint"/>
      <mechanicalReduction>1.0</mechanicalReduction>
    </transmission>
    </xacro:if>

    <!-- fifth element of the arm. x-axis -->
    <joint name="${name}_arm_3_joint" type="revolute">
      <origin xyz="0 0 0.20" rpy="0 0 0"/>
      <axis xyz="0 -1 0"/>
      <limit lower="${-120 * M_PI / 180}" upper="${120 * M_PI / 180}"
             effort="306" velocity="${arm_velocity_scale_factor * 130 * M_PI / 180}" />
      <safety_controller soft_lower_limit="${-118 * M_PI / 180}"
                         soft_upper_limit="${118 * M_PI / 180}"
                         k_position="30"
                         k_velocity="30"/>
      <dynamics damping="1.0"/>
      <parent link="${name}_arm_3_link"/>
      <child link="${name}_arm_4_link"/>
    </joint>

    <link name="${name}_arm_4_link">
      <inertial>
        <mass value="${arm_elem_link_mass}"/>
        <origin rpy="0 0 0" xyz="0 -0.06 ${0.130 - 0.06}"/>
        <cuboid_inertia_def length="0.12" width="0.06" height="0.2600"
                            mass="${arm_elem_link_mass}"/>
      </inertial>

      <xacro:unless value="${visualsimple}">
      <visual>
        <origin rpy="0 0 4.71238898" xyz="0 0 0"/>
        <geometry>
          <mesh filename="package://kuka_lwr4_description/meshes/kuka_colour/link4.obj"/>
        </geometry>
        <material name="Blue"/>
      </visual>
      <visual>
        <origin rpy="0 0 4.71238898" xyz="0 0 0"/>
        <geometry>
          <mesh filename="package://kuka_lwr4_description/meshes/kuka/link4_m.obj"/>
        </geometry>
        <material name="Grey"/>
      </visual>
      <visual>
        <origin rpy="1.570796327 0 0" xyz="0 0 0"/>
        <geometry>
          <mesh filename="package://kuka_lwr4_description/meshes/kuka/kuka_ring.obj"/>
        </geometry>
        <material name="Grey"/>
      </visual>
      </xacro:unless>
      <xacro:if value="${visualsimple}">
      <visual>
        <origin rpy="0 0 0" xyz="0 0 0.15"/>
        <geometry>
          <cylinder length="0.1" radius="0.06"/>
        </geometry>
        <material name="Blue"/>
      </visual>
      <visual>
        <origin rpy="0 0 0" xyz="0 -0.04 0.08"/>
        <geometry>
          <cylinder length="0.05" radius="0.03"/>
        </geometry>
        <material name="Blue"/>
      </visual>
      <visual>
        <origin rpy="0 0 0" xyz="0 -0.04 0"/>
        <geometry>
          <sphere radius="0.06"/>
        </geometry>
        <material name="Blue"/>
      </visual>
      </xacro:if>

      <xacro:unless value="${collisionsimple}">
      <collision>
        <origin xyz="0 0 0.2" rpy="0 ${M_PI} 0"/>
        <geometry>
          <mesh filename="package://kuka_lwr4_description/meshes/lwr/convex/arm_segment_b_convex.stl"/>
        </geometry>
      </collision>
      </xacro:unless>
      <xacro:if value="${collisionsimple}">
      <collision>
        <origin rpy="0 0 0" xyz="0 0 0.15"/>
        <geometry>
          <cylinder length="0.1" radius="0.06"/>
        </geometry>
      </collision>
      <collision>
        <origin rpy="0 0 0" xyz="0 -0.04 0"/>
        <geometry>
          <sphere radius="0.06"/>
        </geometry>
      </collision>
      </xacro:if>
    </link>

    <xacro:if value="${gazebo}">
    <gazebo reference="${name}_arm_4_link">
      <turnGravityOff>true</turnGravityOff>
    </gazebo>
    </xacro:if>

    <xacro:if value="${transmission}">
    <transmission name="${name}_arm_3_trans" type="SimpleTransmission">
      <actuator name="${name}_arm_3_motor"/>
      <joint name="${name}_arm_3_joint"/>
      <mechanicalReduction>1.0</mechanicalReduction>
    </transmission>
    </xacro:if>

    <joint name="${name}_arm_4_joint" type="revolute">
      <origin xyz="0 0 0.20" rpy="0 0 0"/>
      <axis xyz="0 0 1"/>
      <limit lower="${-170 * M_PI / 180}" upper="${170 * M_PI / 180}"
             effort="204" velocity="${arm_velocity_scale_factor * 130 * M_PI / 180}" />
      <safety_controller soft_lower_limit="${-168 * M_PI / 180}"
                         soft_upper_limit="${168 * M_PI / 180}"
                         k_position="30"
                         k_velocity="30"/>
      <dynamics damping="1.0"/>
      <parent link="${name}_arm_4_link"/>
      <child link="${name}_arm_5_link"/>
    </joint>

    <link name="${name}_arm_5_link">
      <inertial>
        <mass value="${arm_elem_link_mass}"/>
        <origin rpy="0 0 0" xyz="0 0 0.124"/>
        <cuboid_inertia_def length="0.12" width="0.06" height="0.248"
                            mass="${arm_elem_link_mass}"/>
      </inertial>

      <xacro:unless value="${visualsimple}">
      <visual>
        <origin rpy="0 0 4.71238898" xyz="0 0 0.19"/>
        <geometry name="${name}_arm_5_geom">
          <mesh filename="package://kuka_lwr4_description/meshes/kuka_colour/link5.obj"/>
        </geometry>
        <material name="Blue"/>
      </visual>
      <visual>
        <origin rpy="0 0 0" xyz="0 0 0"/>
        <geometry>
          <mesh filename="package://kuka_lwr4_description/meshes/kuka/kuka_ring.obj"/>
        </geometry>
        <material name="Grey"/>
      </visual>
      </xacro:unless>
      <xacro:if value="${visualsimple}">
      <visual>
        <origin rpy="0 0 0" xyz="0 0 0.05"/>
        <geometry>
          <cylinder length="0.1" radius="0.06"/>
        </geometry>
        <material name="Blue"/>
      </visual>
      <visual>
        <origin rpy="0 0 0" xyz="0 -0.04 0.12"/>
        <geometry>
          <cylinder length="0.05" radius="0.03"/>
        </geometry>
        <material name="Blue"/>
      </visual>
      <visual>
        <origin rpy="0 0 0" xyz="0 -0.04 0.2"/>
        <geometry>
          <sphere radius="0.06"/>
        </geometry>
        <material name="Blue"/>
      </visual>
      </xacro:if>

      <xacro:unless value="${collisionsimple}">
      <collision>
        <origin xyz="0 0 0" rpy="0 0 0"/>
        <geometry>
          <mesh filename="package://kuka_lwr4_description/meshes/lwr/convex/arm_segment_last_convex.stl"/>
        </geometry>
      </collision>
      </xacro:unless>
      <xacro:if value="${collisionsimple}">
      <collision>
        <origin rpy="0 0 0" xyz="0 0 0.05"/>
        <geometry>
          <cylinder length="0.1" radius="0.06"/>
        </geometry>
      </collision>
      <collision>
        <origin rpy="0 0 0" xyz="0 -0.04 0.2"/>
        <geometry>
          <sphere radius="0.06"/>
        </geometry>
      </collision>
      </xacro:if>
    </link>

    <xacro:if value="${gazebo}">
    <gazebo reference="${name}_arm_5_link">
      <turnGravityOff>true</turnGravityOff>
    </gazebo>
    </xacro:if>
    
    <xacro:if value="${transmission}">
    <transmission name="${name}_arm_4_trans" type="SimpleTransmission">
      <actuator name="${name}_arm_4_motor"/>
      <joint name="${name}_arm_4_joint"/>
      <mechanicalReduction>1.0</mechanicalReduction>
    </transmission>
    </xacro:if>

    <joint name="${name}_arm_5_joint" type="revolute">
      <origin xyz="0 0 0.19" rpy="0 0 0"/>
      <axis xyz="0 1 0"/>
      <limit lower="${-120 * M_PI / 180}" upper="${120 * M_PI / 180}"
             effort="306" velocity="${arm_velocity_scale_factor * 180 * M_PI / 180}" />
      <safety_controller soft_lower_limit="${-118 * M_PI / 180}"
                         soft_upper_limit="${118 * M_PI / 180}"
                         k_position="30"
                         k_velocity="30"/>
      <dynamics damping="1.0"/>
      <parent link="${name}_arm_5_link"/>
      <child link="${name}_arm_6_link"/>
    </joint>

    <link name="${name}_arm_6_link">
      <inertial>
        <mass value="0.2"/>
        <origin rpy="0 0 0" xyz="0 0 0.0625"/>
        <cuboid_inertia_def length="0.125" width="0.125" height="0.125"
                            mass="0.2"/>
      </inertial>

      <xacro:unless value="${visualsimple}">
      <visual>
        <origin rpy="0 0 3.14159265359" xyz="0 0 0"/>
        <geometry>
          <mesh filename="package://kuka_lwr4_description/meshes/kuka/kuka_wrist.obj"/>
        </geometry>
        <material name="Grey"/>
      </visual>
      </xacro:unless>
      <xacro:if value="${visualsimple}">
      <visual>
        <origin rpy="0 0 0" xyz="0 0.01 0"/>
        <geometry>
          <sphere radius="0.07"/>
        </geometry>
        <material name="Grey"/>
      </visual>
      <visual>
        <origin rpy="0 0 0" xyz="0 -0.01 0"/>
        <geometry>
          <sphere radius="0.07"/>
        </geometry>
      </visual>
      </xacro:if>

      <xacro:unless value="${collisionsimple}">
      <collision>
        <origin xyz="0 0 0" rpy="0 0 0"/>
        <geometry>
          <mesh filename="package://kuka_lwr4_description/meshes/lwr/convex/arm_wrist_convex.stl"/>
        </geometry>
      </collision>
      </xacro:unless>
      <xacro:if value="${collisionsimple}">
      <collision>
        <origin rpy="0 0 0" xyz="0 0.01 0"/>
        <geometry>
          <sphere radius="0.07"/>
        </geometry>
        <material name="Grey"/>
      </collision>
      <collision>
        <origin rpy="0 0 0" xyz="0 -0.01 0"/>
        <geometry>
          <sphere radius="0.07"/>
        </geometry>
      </collision>
      </xacro:if>
    </link>

    <xacro:if value="${gazebo}">
    <gazebo reference="${name}_arm_6_link">
      <turnGravityOff>true</turnGravityOff>
    </gazebo>
    </xacro:if>

    <xacro:if value="${transmission}">
    <transmission name="${name}_arm_5_trans" type="SimpleTransmission">
      <actuator name="${name}_arm_5_motor"/>
      <joint name="${name}_arm_5_joint"/>
      <mechanicalReduction>1.0</mechanicalReduction>
    </transmission>
    </xacro:if>

    <joint name="${name}_arm_6_joint" type="revolute">
      <origin xyz="0 0 0.078" rpy="0 0 ${M_PI}"/>
      <axis xyz="0 0 1"/>
      <limit lower="${-170 * M_PI / 180}" upper="${170 * M_PI / 180}"
             effort="204" velocity="${arm_velocity_scale_factor * 180 * M_PI / 180}" />
      <safety_controller soft_lower_limit="${-168 * M_PI / 180}"
                         soft_upper_limit="${168 * M_PI / 180}"
                         k_position="30"
                         k_velocity="30"/>
      <dynamics damping="1.0"/>
      <parent link="${name}_arm_6_link"/>
      <child link="${name}_arm_7_link"/>
    </joint>

<link name="${name}_arm_7_link">
      <inertial>
        <mass value="0.2"/>
        <origin xyz="0 0 0"/>
        <cuboid_inertia_def length="1" width="1" height="1"
                            mass="0.2"/>
      </inertial>

      <xacro:unless value="${visualsimple}">
      <visual>
        <origin xyz="0 0 0" rpy="0 0 0"/>
        <geometry>
          <mesh filename="package://kuka_lwr4_description/meshes/kuka_colour/link7.obj"/>
        </geometry>
        <material name="Grey"/>
      </visual>
      </xacro:unless>
      <xacro:if value="${visualsimple}">
      <visual>
        <origin rpy="0 0 -0.785398163397" xyz="0 0 0"/>
        <geometry>
          <cylinder length="0.05" radius="0.04"/>
        </geometry>
        <material name="Grey"/>
      </visual>
      </xacro:if>

      <xacro:unless value="${collisionsimple}">
      <collision>
        <origin xyz="0 0 0" rpy="0 0 ${right * -1/4 * M_PI}"/>
        <geometry>
          <cylinder radius="0.04" length="0.05"/>
        </geometry>
      </collision>
      </xacro:unless>
      <xacro:if value="${collisionsimple}">
      <collision>
        <origin rpy="0 0 -0.785398163397" xyz="0 0 0"/>
        <geometry>
          <cylinder length="0.05" radius="0.04"/>
        </geometry>
      </collision>
      </xacro:if>
    </link>

    <xacro:if value="${gazebo}">
    <gazebo reference="${name}_arm_7_link">
      <turnGravityOff>true</turnGravityOff>
    </gazebo>
    </xacro:if>
    
    <xacro:if value="${transmission}">
    <transmission name="${name}_arm_6_trans" type="SimpleTransmission">
      <actuator name="${name}_arm_6_motor"/>
      <joint name="${name}_arm_6_joint"/>
      <mechanicalReduction>1.0</mechanicalReduction>
    </transmission>
    </xacro:if>

  </macro>

</robot>
