<?xml version="1.0" ?>
<!-- =================================================================================== -->
<!-- |    This document was autogenerated by xacro from kuka_lwr_arm.urdf.xml          | -->
<!-- |    EDITING THIS FILE BY HAND IS NOT RECOMMENDED                                 | -->
<!-- =================================================================================== -->
<robot name="lwr" xmlns:controller="http://playerstage.sourceforge.net/gazebo/xmlschema/#controller" xmlns:interface="http://playerstage.sourceforge.net/gazebo/xmlschema/#interface" xmlns:sensor="http://playerstage.sourceforge.net/gazebo/xmlschema/#sensor" xmlns:xacro="http://playerstage.sourceforge.net/gazebo/xmlschema/#interface">
  <material name="DarkGrey">
    <color rgba="0.3 0.3 0.3 1.0"/>
  </material>
  <material name="Red">
    <color rgba="0.3 0.3 0.3 1.0"/>
  </material>
  <material name="Black">
    <color rgba="0 0 0 1.0"/>
  </material>
  <material name="Orange">
    <color rgba="1.0 0.487 0 1.0"/>
  </material>
  <material name="Silver">
    <color rgba="1.0 1.0 1.0 1.0"/>
  </material>
  <material name="Grey">
    <color rgba="0.7 0.7 0.7 1.0"/>
  </material>
  <material name="Blue">
    <color rgba="0.0 0.0 0.8 1.0"/>
  </material>
  <material name="HandGray">
    <color rgba="0.953 0.996 0.694 1.0"/>
  </material>
  <material name="SickBlue">
    <color rgba="0.3058 0.5921 0.7294 1.0"/>
  </material>
  <link name="world_frame">
    <visual>
      <origin rpy="0 0 0" xyz="0 0 -0.02"/>
      <geometry>
        <box size="0.7 0.75 0.04"/>
      </geometry>
      <material name="DarkGrey"/>
    </visual>
    <collision>
      <origin rpy="0 0 0" xyz="0 0 -0.02"/>
      <geometry>
        <box size="0.7 0.75 0.04"/>
      </geometry>
    </collision>
  </link>
  <joint name="world_frame_lwr_arm_base_joint" type="fixed">
    <origin rpy="0 0 0" xyz="0 0 0"/>
    <parent link="world_frame"/>
    <child link="base"/>
  </joint>
  <link name="base">
    <inertial>
      <mass value="2.0"/>
      <origin xyz="0 0 0.055"/>
      <inertia ixx="0.00381666666667" ixy="0" ixz="0" iyy="0.0036" iyz="0" izz="0.00381666666667"/>
    </inertial>
    <visual>
      <origin rpy="0 0 0" xyz="0.04 0 0.03"/>
      <geometry>
        <box size="0.08 0.12 0.06"/>
      </geometry>
      <material name="Blue"/>
    </visual>
    <visual>
      <origin rpy="0 0 0" xyz="0 0 0.05"/>
      <geometry>
        <cylinder length="0.1" radius="0.06"/>
      </geometry>
      <material name="Blue"/>
    </visual>
    <collision>
      <origin rpy="0 0 0" xyz="0.04 0 0.03"/>
      <geometry>
        <box size="0.08 0.12 0.06"/>
      </geometry>
    </collision>
    <collision>
      <origin rpy="0 0 0" xyz="0 0 0.05"/>
      <geometry>
        <cylinder length="0.1" radius="0.06"/>
      </geometry>
    </collision>
  </link>
  <joint name="lwr_arm_0_joint" type="revolute">
    <origin rpy="0 0 3.14159265359" xyz="0 0 0.11"/>
    <axis xyz="0 0 1"/>
    <limit effort="204" lower="-2.96705972839" upper="2.96705972839" velocity="1.91986217719"/>
    <safety_controller k_position="30" k_velocity="30" soft_lower_limit="-2.93215314335" soft_upper_limit="2.93215314335"/>
    <dynamics damping="1.0"/>
    <parent link="base"/>
    <child link="lwr_arm_1_link"/>
  </joint>
  <link name="lwr_arm_1_link">
    <inertial>
      <mass value="2.0"/>
      <origin rpy="0 0 0" xyz="0 -0.06 0.130"/>
      <inertia ixx="0.0136666666667" ixy="0" ixz="0" iyy="0.003" iyz="0" izz="0.0118666666667"/>
    </inertial>
    <visual>
      <origin rpy="0 0 0" xyz="0 0 0.05"/>
      <geometry>
        <cylinder length="0.1" radius="0.06"/>
      </geometry>
      <material name="Blue"/>
    </visual>
    <visual>
      <origin rpy="0 0 0" xyz="0 -0.04 0.12"/>
      <geometry>
        <cylinder length="0.05" radius="0.03"/>
      </geometry>
      <material name="Blue"/>
    </visual>
    <visual>
      <origin rpy="0 0 0" xyz="0 -0.04 0.2"/>
      <geometry>
        <sphere radius="0.06"/>
      </geometry>
      <material name="Blue"/>
    </visual>
    <collision>
      <origin rpy="0 0 0" xyz="0 0 0.05"/>
      <geometry>
        <cylinder length="0.1" radius="0.06"/>
      </geometry>
    </collision>
    <collision>
      <origin rpy="0 0 0" xyz="0 -0.04 0.2"/>
      <geometry>
        <sphere radius="0.06"/>
      </geometry>
    </collision>
  </link>
  <!-- Third segment of the arm. Joint along y-axis -->
  <joint name="lwr_arm_1_joint" type="revolute">
    <origin rpy="0 0 0" xyz="0 0 0.2"/>
    <axis xyz="0 1 0"/>
    <limit effort="306" lower="-2.09439510239" upper="2.09439510239" velocity="1.91986217719"/>
    <safety_controller k_position="30" k_velocity="30" soft_lower_limit="-2.05948851735" soft_upper_limit="2.05948851735"/>
    <dynamics damping="1.0" friction="10"/>
    <parent link="lwr_arm_1_link"/>
    <child link="lwr_arm_2_link"/>
  </joint>
  <link name="lwr_arm_2_link">
    <inertial>
      <mass value="2.0"/>
      <origin rpy="0 0 0" xyz="0 0.06 0.07"/>
      <inertia ixx="0.0136666666667" ixy="0" ixz="0" iyy="0.003" iyz="0" izz="0.0118666666667"/>
    </inertial>
    <visual>
      <origin rpy="0 0 0" xyz="0 0 0.15"/>
      <geometry>
        <cylinder length="0.1" radius="0.06"/>
      </geometry>
      <material name="Blue"/>
    </visual>
    <visual>
      <origin rpy="0 0 0" xyz="0 0.04 0.08"/>
      <geometry>
        <cylinder length="0.05" radius="0.03"/>
      </geometry>
      <material name="Blue"/>
    </visual>
    <visual>
      <origin rpy="0 0 0" xyz="0 0.04 0"/>
      <geometry>
        <sphere radius="0.06"/>
      </geometry>
      <material name="Blue"/>
    </visual>
    <collision>
      <origin rpy="0 0 0" xyz="0 0 0.15"/>
      <geometry>
        <cylinder length="0.1" radius="0.06"/>
      </geometry>
    </collision>
    <collision>
      <origin rpy="0 0 0" xyz="0 0.04 0"/>
      <geometry>
        <sphere radius="0.06"/>
      </geometry>
    </collision>
  </link>
  <joint name="lwr_arm_2_joint" type="revolute">
    <origin rpy="0 0 0" xyz="0 0 0.20"/>
    <axis xyz="0 0 1"/>
    <limit effort="204" lower="-2.96705972839" upper="2.96705972839" velocity="2.26892802759"/>
    <safety_controller k_position="30" k_velocity="30" soft_lower_limit="-2.93215314335" soft_upper_limit="2.93215314335"/>
    <dynamics damping="1.0"/>
    <parent link="lwr_arm_2_link"/>
    <child link="lwr_arm_3_link"/>
  </joint>
  <link name="lwr_arm_3_link">
    <inertial>
      <mass value="2.0"/>
      <origin rpy="0 0 0" xyz="0 0.06 0.130"/>
      <inertia ixx="0.0136666666667" ixy="0" ixz="0" iyy="0.003" iyz="0" izz="0.0118666666667"/>
    </inertial>
    <visual>
      <origin rpy="0 0 0" xyz="0 0 0.05"/>
      <geometry>
        <cylinder length="0.1" radius="0.06"/>
      </geometry>
      <material name="Blue"/>
    </visual>
    <visual>
      <origin rpy="0 0 0" xyz="0 0.04 0.12"/>
      <geometry>
        <cylinder length="0.05" radius="0.03"/>
      </geometry>
      <material name="Blue"/>
    </visual>
    <visual>
      <origin rpy="0 0 0" xyz="0 0.04 0.2"/>
      <geometry>
        <sphere radius="0.06"/>
      </geometry>
      <material name="Blue"/>
    </visual>
    <collision>
      <origin rpy="0 0 0" xyz="0 0 0.05"/>
      <geometry>
        <cylinder length="0.1" radius="0.06"/>
      </geometry>
    </collision>
    <collision>
      <origin rpy="0 0 0" xyz="0 0.04 0.2"/>
      <geometry>
        <sphere radius="0.06"/>
      </geometry>
    </collision>
  </link>
  <!-- fifth element of the arm. x-axis -->
  <joint name="lwr_arm_3_joint" type="revolute">
    <origin rpy="0 0 0" xyz="0 0 0.20"/>
    <axis xyz="0 -1 0"/>
    <limit effort="306" lower="-2.09439510239" upper="2.09439510239" velocity="2.26892802759"/>
    <safety_controller k_position="30" k_velocity="30" soft_lower_limit="-2.05948851735" soft_upper_limit="2.05948851735"/>
    <dynamics damping="1.0"/>
    <parent link="lwr_arm_3_link"/>
    <child link="lwr_arm_4_link"/>
  </joint>
  <link name="lwr_arm_4_link">
    <inertial>
      <mass value="2.0"/>
      <origin rpy="0 0 0" xyz="0 -0.06 0.07"/>
      <inertia ixx="0.0136666666667" ixy="0" ixz="0" iyy="0.003" iyz="0" izz="0.0118666666667"/>
    </inertial>
    <visual>
      <origin rpy="0 0 0" xyz="0 0 0.15"/>
      <geometry>
        <cylinder length="0.1" radius="0.06"/>
      </geometry>
      <material name="Blue"/>
    </visual>
    <visual>
      <origin rpy="0 0 0" xyz="0 -0.04 0.08"/>
      <geometry>
        <cylinder length="0.05" radius="0.03"/>
      </geometry>
      <material name="Blue"/>
    </visual>
    <visual>
      <origin rpy="0 0 0" xyz="0 -0.04 0"/>
      <geometry>
        <sphere radius="0.06"/>
      </geometry>
      <material name="Blue"/>
    </visual>
    <collision>
      <origin rpy="0 0 0" xyz="0 0 0.15"/>
      <geometry>
        <cylinder length="0.1" radius="0.06"/>
      </geometry>
    </collision>
    <collision>
      <origin rpy="0 0 0" xyz="0 -0.04 0"/>
      <geometry>
        <sphere radius="0.06"/>
      </geometry>
    </collision>
  </link>
  <joint name="lwr_arm_4_joint" type="revolute">
    <origin rpy="0 0 0" xyz="0 0 0.20"/>
    <axis xyz="0 0 1"/>
    <limit effort="204" lower="-2.96705972839" upper="2.96705972839" velocity="2.26892802759"/>
    <safety_controller k_position="30" k_velocity="30" soft_lower_limit="-2.93215314335" soft_upper_limit="2.93215314335"/>
    <dynamics damping="1.0"/>
    <parent link="lwr_arm_4_link"/>
    <child link="lwr_arm_5_link"/>
  </joint>
  <link name="lwr_arm_5_link">
    <inertial>
      <mass value="2.0"/>
      <origin rpy="0 0 0" xyz="0 0 0.124"/>
      <inertia ixx="0.0126506666667" ixy="0" ixz="0" iyy="0.003" iyz="0" izz="0.0108506666667"/>
    </inertial>
    <visual>
      <origin rpy="0 0 0" xyz="0 0 0.05"/>
      <geometry>
        <cylinder length="0.1" radius="0.06"/>
      </geometry>
      <material name="Blue"/>
    </visual>
    <visual>
      <origin rpy="0 0 0" xyz="0 -0.04 0.12"/>
      <geometry>
        <cylinder length="0.05" radius="0.03"/>
      </geometry>
      <material name="Blue"/>
    </visual>
    <visual>
      <origin rpy="0 0 0" xyz="0 -0.04 0.2"/>
      <geometry>
        <sphere radius="0.06"/>
      </geometry>
      <material name="Blue"/>
    </visual>
    <collision>
      <origin rpy="0 0 0" xyz="0 0 0.05"/>
      <geometry>
        <cylinder length="0.1" radius="0.06"/>
      </geometry>
    </collision>
    <collision>
      <origin rpy="0 0 0" xyz="0 -0.04 0.2"/>
      <geometry>
        <sphere radius="0.06"/>
      </geometry>
    </collision>
  </link>
  <joint name="lwr_arm_5_joint" type="revolute">
    <origin rpy="0 0 0" xyz="0 0 0.19"/>
    <axis xyz="0 1 0"/>
    <limit effort="306" lower="-2.09439510239" upper="2.09439510239" velocity="3.14159265359"/>
    <safety_controller k_position="30" k_velocity="30" soft_lower_limit="-2.05948851735" soft_upper_limit="2.05948851735"/>
    <dynamics damping="1.0"/>
    <parent link="lwr_arm_5_link"/>
    <child link="lwr_arm_6_link"/>
  </joint>
  <link name="lwr_arm_6_link">
    <inertial>
      <mass value="0.2"/>
      <origin rpy="0 0 0" xyz="0 0 0.0625"/>
      <inertia ixx="0.000520833333333" ixy="0" ixz="0" iyy="0.000520833333333" iyz="0" izz="0.000520833333333"/>
    </inertial>
    <visual>
      <origin rpy="0 0 0" xyz="0 0.01 0"/>
      <geometry>
        <sphere radius="0.07"/>
      </geometry>
      <material name="Grey"/>
    </visual>
    <visual>
      <origin rpy="0 0 0" xyz="0 -0.01 0"/>
      <geometry>
        <sphere radius="0.07"/>
      </geometry>
    </visual>
    <collision>
      <origin rpy="0 0 0" xyz="0 0.01 0"/>
      <geometry>
        <sphere radius="0.07"/>
      </geometry>
      <material name="Grey"/>
    </collision>
    <collision>
      <origin rpy="0 0 0" xyz="0 -0.01 0"/>
      <geometry>
        <sphere radius="0.07"/>
      </geometry>
    </collision>
  </link>
  <joint name="lwr_arm_6_joint" type="revolute">
    <origin rpy="0 0 3.14159265359" xyz="0 0 0.078"/>
    <axis xyz="0 0 1"/>
    <limit effort="204" lower="-2.96705972839" upper="2.96705972839" velocity="3.14159265359"/>
    <safety_controller k_position="30" k_velocity="30" soft_lower_limit="-2.93215314335" soft_upper_limit="2.93215314335"/>
    <dynamics damping="1.0"/>
    <parent link="lwr_arm_6_link"/>
    <child link="lwr_arm_7_link"/>
  </joint>
  <link name="lwr_arm_7_link">
    <inertial>
      <mass value="0.2"/>
      <origin xyz="0 0 0"/>
      <inertia ixx="0.0333333333333" ixy="0" ixz="0" iyy="0.0333333333333" iyz="0" izz="0.0333333333333"/>
    </inertial>
    <visual>
      <origin rpy="0 0 -0.785398163397" xyz="0 0 0"/>
      <geometry>
        <cylinder length="0.05" radius="0.04"/>
      </geometry>
      <material name="Grey"/>
    </visual>
    <collision>
      <origin rpy="0 0 -0.785398163397" xyz="0 0 0"/>
      <geometry>
        <cylinder length="0.05" radius="0.04"/>
      </geometry>
    </collision>
  </link>
  <joint name="pen_base_joint" type="fixed">
    <origin rpy="0 0 0" xyz="0 0 0.075"/>
    <parent link="lwr_arm_7_link"/>
    <child link="pen_base_link"/>
  </joint>
  <link name="pen_base_link">
    <inertial>
      <origin rpy="0 0 0" xyz="0 0 0"/>
      <mass value="1"/>
      <inertia ixx="0.01" ixy="0" ixz="0" iyy="0.01" iyz="0" izz="0.01"/>
    </inertial>
    <visual>
      <origin rpy="0 0 0" xyz="0 0 0"/>
      <geometry>
        <cylinder length="0.15" radius="0.005"/>
      </geometry>
      <material name="Grey"/>
    </visual>
    <collision>
      <origin rpy="0 0 0" xyz="0 0 0"/>
      <geometry>
        <cylinder length="0.15" radius="0.005"/>
      </geometry>
    </collision>
  </link>
  <joint name="pen_tip_joint" type="fixed">
    <origin rpy="0 0 0" xyz="0 0 0.075"/>
    <parent link="pen_base_link"/>
    <child link="pen_tip_link"/>
  </joint>
  <link name="pen_tip_link">
    <inertial>
      <origin rpy="0 0 0" xyz="0 0 0"/>
      <mass value="1"/>
      <inertia ixx="0.01" ixy="0" ixz="0" iyy="0.01" iyz="0" izz="0.01"/>
    </inertial>
    <visual>
      <origin rpy="0 0 0" xyz="0 0 0"/>
      <geometry>
        <sphere radius="0.008"/>
      </geometry>
      <material name="Orange"/>
    </visual>
  </link>
  <joint name="pen_ori_joint" type="fixed">
    <origin rpy="0 0 0" xyz="0 0 0.075"/>
    <parent link="lwr_arm_7_link"/>
    <child link="pen_ori_link"/>
  </joint>
  <link name="pen_ori_link">
    <inertial>
      <origin rpy="0 0 0" xyz="0 0 0"/>
      <mass value="1"/>
      <inertia ixx="0.01" ixy="0" ixz="0" iyy="0.01" iyz="0" izz="0.01"/>
    </inertial>
    <visual>
      <origin rpy="0 0 0" xyz="0 0 0"/>
      <geometry>
        <cylinder length="0.075" radius="0.005"/>
      </geometry>
      <material name="Non">
        <color rgba="0 0 0 0"/>
      </material>
    </visual>
  </link>
</robot>

